Traceback (most recent call last):
  File "D:\nchaurasia\Python-Architect\connect2tech.in-Python\exception\UsingTraceback.py", line 9, in <module>
    print ("Fourth element = ", (a[3]))
IndexError: list index out of range
